Workbook

Sheet Result>

Sheet Final_data
I4: Rate of NPV calculation | J4: 0.54177842
I5: Total NPV | J5: =SUM(E9:E156) -> 4.6369096e-06
I6: XIRR | J6: =J4 -> 0.54177842
B8: Date | C8: Cashflow | D8: Trade Type | E8: NPV
B9: 45026 | C9: 20880 | D9: =IF(C9>0,"sell","buy") -> sell | E9: =C9/(1+$J$4)^((B9-$B$9)/365) -> 20880
B10: 45028 | C10: 9588.28 | D10: =IF(C10>0,"sell","buy") -> sell | E10: =C10/(1+$J$4)^((B10-$B$9)/365) -> 9565.5611
B11: 45029 | C11: 10608.55 | D11: =IF(C11>0,"sell","buy") -> sell | E11: =C11/(1+$J$4)^((B11-$B$9)/365) -> 10570.868
B12: 45034 | C12: 145280 | D12: =IF(C12>0,"sell","buy") -> sell | E12: =C12/(1+$J$4)^((B12-$B$9)/365) -> 143907.96
B13: 45035 | C13: 58863.9 | D13: =IF(C13>0,"sell","buy") -> sell | E13: =C13/(1+$J$4)^((B13-$B$9)/365) -> 58238.861
B14: 45036 | C14: 1300 | D14: =IF(C14>0,"sell","buy") -> sell | E14: =C14/(1+$J$4)^((B14-$B$9)/365) -> 1284.6714
B15: 45037 | C15: 18880.5 | D15: =IF(C15>0,"sell","buy") -> sell | E15: =C15/(1+$J$4)^((B15-$B$9)/365) -> 18635.759
B16: 45049 | C16: 116000 | D16: =IF(C16>0,"sell","buy") -> sell | E16: =C16/(1+$J$4)^((B16-$B$9)/365) -> 112878.19
B17: 45051 | C17: 825.5 | D17: =IF(C17>0,"sell","buy") -> sell | E17: =C17/(1+$J$4)^((B17-$B$9)/365) -> 801.38067
B18: 45061 | C18: 69138.2 | D18: =IF(C18>0,"sell","buy") -> sell | E18: =C18/(1+$J$4)^((B18-$B$9)/365) -> 66326.727
B19: 45062 | C19: -70000 | D19: =IF(C19>0,"sell","buy") -> buy | E19: =C19/(1+$J$4)^((B19-$B$9)/365) -> -67073.877
B20: 45063 | C20: -51450 | D20: =IF(C20>0,"sell","buy") -> buy | E20: =C20/(1+$J$4)^((B20-$B$9)/365) -> -49240.859
... B88: 46111 | C88: -1344240.2 | D88: =IF(C88>0,"sell","buy") -> buy | E88: =C88/(1+$J$4)^((B88-$B$9)/365) -> -371160.95
B89: 46126 | C89: =Open_positions!G3 -> 210205 | D89: =IF(C89>0,"sell","buy") -> sell | E89: =C89/(1+$J$4)^((B89-$B$9)/365) -> 57016.626
B90: 46126 | C90: =Open_positions!G4 -> 111888 | D90: =IF(C90>0,"sell","buy") -> sell | E90: =C90/(1+$J$4)^((B90-$B$9)/365) -> 30348.832
B91: 46126 | C91: =Open_positions!G5 -> 194550 | D91: =IF(C91>0,"sell","buy") -> sell | E91: =C91/(1+$J$4)^((B91-$B$9)/365) -> 52770.318
B92: 46126 | C92: =Open_positions!G6 -> 395379.6 | D92: =IF(C92>0,"sell","buy") -> sell | E92: =C92/(1+$J$4)^((B92-$B$9)/365) -> 107243.93
B93: 46126 | C93: =Open_positions!G7 -> 71580.6 | D93: =IF(C93>0,"sell","buy") -> sell | E93: =C93/(1+$J$4)^((B93-$B$9)/365) -> 19415.734
B94: 46126 | C94: =Open_positions!G8 -> 985291.2 | D94: =IF(C94>0,"sell","buy") -> sell | E94: =C94/(1+$J$4)^((B94-$B$9)/365) -> 267253.3
B95: 46126 | C95: =Open_positions!G9 -> 167240 | D95: =IF(C95>0,"sell","buy") -> sell | E95: =C95/(1+$J$4)^((B95-$B$9)/365) -> 45362.672
B96: 46126 | C96: =Open_positions!G10 -> 160468.75 | D96: =IF(C96>0,"sell","buy") -> sell | E96: =C96/(1+$J$4)^((B96-$B$9)/365) -> 43526.019
B97: 46126 | C97: =Open_positions!G11 -> 200504 | D97: =IF(C97>0,"sell","buy") -> sell | E97: =C97/(1+$J$4)^((B97-$B$9)/365) -> 54385.298
B98: 46126 | C98: =Open_positions!G12 -> 773437.7 | D98: =IF(C98>0,"sell","buy") -> sell | E98: =C98/(1+$J$4)^((B98-$B$9)/365) -> 209789.53
B99: 46126 | C99: =Open_positions!G13 -> 411837.75 | D99: =IF(C99>0,"sell","buy") -> sell | E99: =C99/(1+$J$4)^((B99-$B$9)/365) -> 111708.09
B100: 46126 | C100: =Open_positions!G14 -> 411560 | D100: =IF(C100>0,"sell","buy") -> sell | E100: =C100/(1+$J$4)^((B100-$B$9)/365) -> 111632.75
... B156: 46126 | C156: =Open_positions!G70 -> 695960 | D156: =IF(C156>0,"sell","buy") -> sell | E156: =C156/(1+$J$4)^((B156-$B$9)/365) -> 188774.25
B157: TOTAL | C157: =SUM(C9:C156) -> 8357822.2 | E157: =SUM(E9:E156) -> 4.6369096e-06

Sheet Documentation>

Sheet Section 1
B2: XIRR Financial Modeling Documentation
B4: Zerodha Tradebook — Goal Seek Validation Report
B9: Tradebook Data Clarification Points
A11: # | B11: Cash Flow Sign Convention: BUY transactions are recorded as negative cash outflows (capital deployed); SELL transactions are recorded as positive cash inflows (capital recovered). This convention is applied consistently across all 148 date-aggregated rows in Final_data. Total outflows: ₹1,68,46,932.94; Total inflows: ₹2,52,04,755.17.
A13: # | B13: Date Normalization Method: All transaction timestamps are stripped to date-only precision (time component = 00:00:00). Multiple transactions on the same calendar date are aggregated into a single net cash flow via Sum of Cashflow (pivot from Pivot_temp sheet). This reduces 831 raw trades to 148 date-level rows.
A15: # | B15: Edge Case A — Missing BUY (10 rows, 10-Apr-2023 to 15-May-2023): The dataset opens with 10 consecutive positive (SELL) cash flows before the first BUY appears on 16-May-2023. These represent sales of positions whose purchase transactions are absent from the tradebook. [ASSUMPTION: Zero acquisition cost on 10-Apr-2023 (earliest date) — rationale: no BUY record exists in the Zerodha export; treating as ₹0 cost entry preserves cash flow integrity without fabricating a number. This is the most conservative treatment.]
A17: # | B17: Edge Case B — Missing SELL (Open Positions): 68 open positions (held as of 14-Apr-2026) have no SELL record. [ASSUMPTION: All open positions closed on 14-Apr-2026 at NSE market closing prices sourced from the Open_positions sheet, column "Market price as on 14-04-2026." The resulting sell-side cash flows are appended as positive entries on that date, totalling ₹1,87,57,940.00.]
A19: # | B19: Open Position Treatment: The Open_positions sheet provides per-symbol market prices as on 14-Apr-2026. Market value cash flows (Qty × Market Price) are entered as positive inflows on 14-Apr-2026 in Final_data, mirroring a hypothetical same-day liquidation. This is the standard XIRR treatment for unrealised positions.
A21: # | B21: Data Sorting / Ordering Logic: All 148 aggregated rows are sorted in ascending chronological order (earliest date first: 10-Apr-2023; latest: 14-Apr-2026). This is mandatory for Excel's XIRR() function and for the Goal Seek NPV formula to compute day-count offsets correctly from the anchor date.
A23: # | B23: Preprocessing Applied: Raw Merged_Data (831 rows, 6 columns) → date aggregation via pivot (Pivot_temp) → trade-type tagging (buy/sell) → sign enforcement (buy = negative, sell = positive) → open position market value appended → final 148-row cash flow series in Final_data.
A25: # | B25: XIRR Failure Root Cause: Excel's XIRR() requires the first cash flow to be negative (an outflow). In this dataset, the first 10 cash flows are all positive (SELL without a preceding BUY), violating the sign-alternation prerequisite. Excel cannot find a valid initial guess to begin iteration, returning #NUM!. This is not a convergence failure — it is a structural sign-pattern violation. [ASSUMPTION: XIRR error type = #NUM! — rationale: dataset starts with all-positive CFs, which is the canonical trigger for this error in Excel 365.]

Sheet DATA>
A1: DATA

Sheet Merged_Data
A1: Symbol | B1: Trade Date | C1: Trade Type | D1: Quantity | E1: Price | F1: Cashflow
A2: BOHRAIND | B2: 46054 | C2: sell | D2: 1000 | E2: 19 | F2: =IF(Tradebook_2023_2026[[#This Row],[Trade Type]]="buy",-(Tradebook_2023_2026[[#This Row],[Quantity]]*Tradebook_2023_2026[[#This Row],[Price]]),(Tradebook_2023_2026[[#This Row],[Quantity]]*Tradebook_2023_2026[[#This Row],[Price]])) -> 19000
A3: BOHRAIND | B3: 46054 | C3: sell | D3: 1 | E3: 18.5 | F3: =IF(Tradebook_2023_2026[[#This Row],[Trade Type]]="buy",-(Tradebook_2023_2026[[#This Row],[Quantity]]*Tradebook_2023_2026[[#This Row],[Price]]),(Tradebook_2023_2026[[#This Row],[Quantity]]*Tradebook_2023_2026[[#This Row],[Price]])) -> 18.5
A4: BOHRAIND | B4: 46054 | C4: sell | D4: 55 | E4: 18.5 | F4: =IF(Tradebook_2023_2026[[#This Row],[Trade Type]]="buy",-(Tradebook_2023_2026[[#This Row],[Quantity]]*Tradebook_2023_2026[[#This Row],[Price]]),(Tradebook_2023_2026[[#This Row],[Quantity]]*Tradebook_2023_2026[[#This Row],[Price]])) -> 1017.5
A5: BOHRAIND | B5: 46054 | C5: sell | D5: 944 | E5: 18.5 | F5: =IF(Tradebook_2023_2026[[#This Row],[Trade Type]]="buy",-(Tradebook_2023_2026[[#This Row],[Quantity]]*Tradebook_2023_2026[[#This Row],[Price]]),(Tradebook_2023_2026[[#This Row],[Quantity]]*Tradebook_2023_2026[[#This Row],[Price]])) -> 17464
A6: PAYTM | B6: 46054 | C6: buy | D6: 21 | E6: 1064.7 | F6: =IF(Tradebook_2023_2026[[#This Row],[Trade Type]]="buy",-(Tradebook_2023_2026[[#This Row],[Quantity]]*Tradebook_2023_2026[[#This Row],[Price]]),(Tradebook_2023_2026[[#This Row],[Quantity]]*Tradebook_2023_2026[[#This Row],[Price]])) -> -22358.7
A7: PAYTM | B7: 46054 | C7: buy | D7: 4 | E7: 1064.65 | F7: =IF(Tradebook_2023_2026[[#This Row],[Trade Type]]="buy",-(Tradebook_2023_2026[[#This Row],[Quantity]]*Tradebook_2023_2026[[#This Row],[Price]]),(Tradebook_2023_2026[[#This Row],[Quantity]]*Tradebook_2023_2026[[#This Row],[Price]])) -> -4258.6
A8: GOKEX | B8: 46055 | C8: buy | D8: 1000 | E8: 609.25 | F8: =IF(Tradebook_2023_2026[[#This Row],[Trade Type]]="buy",-(Tradebook_2023_2026[[#This Row],[Quantity]]*Tradebook_2023_2026[[#This Row],[Price]]),(Tradebook_2023_2026[[#This Row],[Quantity]]*Tradebook_2023_2026[[#This Row],[Price]])) -> -609250
A9: GOKEX | B9: 46055 | C9: buy | D9: 10 | E9: 609.25 | F9: =IF(Tradebook_2023_2026[[#This Row],[Trade Type]]="buy",-(Tradebook_2023_2026[[#This Row],[Quantity]]*Tradebook_2023_2026[[#This Row],[Price]]),(Tradebook_2023_2026[[#This Row],[Quantity]]*Tradebook_2023_2026[[#This Row],[Price]])) -> -6092.5
A10: GOKEX | B10: 46055 | C10: buy | D10: 203 | E10: 609.25 | F10: =IF(Tradebook_2023_2026[[#This Row],[Trade Type]]="buy",-(Tradebook_2023_2026[[#This Row],[Quantity]]*Tradebook_2023_2026[[#This Row],[Price]]),(Tradebook_2023_2026[[#This Row],[Quantity]]*Tradebook_2023_2026[[#This Row],[Price]])) -> -123677.75
A11: GOKEX | B11: 46055 | C11: buy | D11: 2 | E11: 609.25 | F11: =IF(Tradebook_2023_2026[[#This Row],[Trade Type]]="buy",-(Tradebook_2023_2026[[#This Row],[Quantity]]*Tradebook_2023_2026[[#This Row],[Price]]),(Tradebook_2023_2026[[#This Row],[Quantity]]*Tradebook_2023_2026[[#This Row],[Price]])) -> -1218.5
A12: GOKEX | B12: 46055 | C12: buy | D12: 276 | E12: 609.25 | F12: =IF(Tradebook_2023_2026[[#This Row],[Trade Type]]="buy",-(Tradebook_2023_2026[[#This Row],[Quantity]]*Tradebook_2023_2026[[#This Row],[Price]]),(Tradebook_2023_2026[[#This Row],[Quantity]]*Tradebook_2023_2026[[#This Row],[Price]])) -> -168153
A13: GOKEX | B13: 46055 | C13: buy | D13: 4 | E13: 609.25 | F13: =IF(Tradebook_2023_2026[[#This Row],[Trade Type]]="buy",-(Tradebook_2023_2026[[#This Row],[Quantity]]*Tradebook_2023_2026[[#This Row],[Price]]),(Tradebook_2023_2026[[#This Row],[Quantity]]*Tradebook_2023_2026[[#This Row],[Price]])) -> -2437
... A832: LKMEHTA-MT | B832: 45709 | C832: sell | D832: 1600 | E832: 71 | F832: =IF(Tradebook_2023_2026[[#This Row],[Trade Type]]="buy",-(Tradebook_2023_2026[[#This Row],[Quantity]]*Tradebook_2023_2026[[#This Row],[Price]]),(Tradebook_2023_2026[[#This Row],[Quantity]]*Tradebook_2023_2026[[#This Row],[Price]])) -> 113600

Sheet Pivot_temp
B2: Row Labels | C2: Sum of Cashflow
B3: 45026 | C3: 20880
B4: 45028 | C4: 9588.28
B5: 45029 | C5: 10608.55
B6: 45034 | C6: 145280
B7: 45035 | C7: 58863.9
B8: 45036 | C8: 1300
B9: 45037 | C9: 18880.5
B10: 45049 | C10: 116000
B11: 45051 | C11: 825.5
B12: 45061 | C12: 69138.2
B13: 45062 | C13: -70000
B14: 45063 | C14: -51450
... B82: 46111 | C82: -1344240.2

Sheet Temp_Data
B2: Symbols | C2: Buy QTY | D2: Buy Price | E2: Sell QTY | F2: Sell Price | G2: Sum of Cashflow | H2: diffrence
B3: ABB | C3: 34 | D3: 17259 | G3: -195602 | H3: =Table3[[#This Row],[Buy QTY]]-Table3[[#This Row],[Sell QTY]] -> 34
B4: ABCGAS | C4: 945 | D4: 193.46 | G4: -36820.2 | H4: =Table3[[#This Row],[Buy QTY]]-Table3[[#This Row],[Sell QTY]] -> 945
B5: ABFRL | C5: 3000 | D5: 7918.75 | G5: -950250 | H5: =Table3[[#This Row],[Buy QTY]]-Table3[[#This Row],[Sell QTY]] -> 3000
B6: AGSTRA | E6: 97 | F6: 57 | G6: 5529 | H6: =Table3[[#This Row],[Buy QTY]]-Table3[[#This Row],[Sell QTY]] -> -97
B7: AMBIKCO | E7: 31 | F7: 17615.4 | G7: 49641.2 | H7: =Table3[[#This Row],[Buy QTY]]-Table3[[#This Row],[Sell QTY]] -> -31
B8: ANUBHAV | C8: 2723 | D8: 45.58 | G8: -30661.7 | H8: =Table3[[#This Row],[Buy QTY]]-Table3[[#This Row],[Sell QTY]] -> 2723
B9: APOLLOHOSP | E9: 1 | F9: 7452.6499 | G9: 7452.6499 | H9: =Table3[[#This Row],[Buy QTY]]-Table3[[#This Row],[Sell QTY]] -> -1
B10: ARVSMART | E10: 42 | F10: 3815.4 | G10: 13353.9 | H10: =Table3[[#This Row],[Buy QTY]]-Table3[[#This Row],[Sell QTY]] -> -42
B11: ASTERDM | E11: 37 | F11: 666.85 | G11: 24673.45 | H11: =Table3[[#This Row],[Buy QTY]]-Table3[[#This Row],[Sell QTY]] -> -37
B12: AUROIMPEX | E12: 1600 | F12: 75 | G12: 120000 | H12: =Table3[[#This Row],[Buy QTY]]-Table3[[#This Row],[Sell QTY]] -> -1600
B13: AXISBANK | C13: 57 | D13: 1897 | G13: -54064.5 | H13: =Table3[[#This Row],[Buy QTY]]-Table3[[#This Row],[Sell QTY]] -> 57
B14: BAJFINANCE | C14: 144 | D14: 55456 | G14: -998208 | H14: =Table3[[#This Row],[Buy QTY]]-Table3[[#This Row],[Sell QTY]] -> 144
B15: BDL | C15: 1354 | D15: 12916.7 | E15: 1254 | F15: 12538.45 | G15: -106776.25 | H15: =Table3[[#This Row],[Buy QTY]]-Table3[[#This Row],[Sell QTY]] -> 100
B16: BEDMUTHA | E16: 200 | F16: 59 | G16: 11800 | H16: =Table3[[#This Row],[Buy QTY]]-Table3[[#This Row],[Sell QTY]] -> -200
B17: BNRSEC | C17: 1625 | D17: 62.5 | G17: -27857.5 | H17: =Table3[[#This Row],[Buy QTY]]-Table3[[#This Row],[Sell QTY]] -> 1625
B18: BOHRAIND | E18: 3000 | F18: 94.55 | G18: 57550 | H18: =Table3[[#This Row],[Buy QTY]]-Table3[[#This Row],[Sell QTY]] -> -3000
B19: BRITANNIA | C19: 40 | D19: 33277 | G19: -221847.5 | H19: =Table3[[#This Row],[Buy QTY]]-Table3[[#This Row],[Sell QTY]] -> 40
B20: CAMS | C20: 556 | D20: 3980.35 | E20: 278 | F20: 1286.15 | G20: -196880.05 | H20: =Table3[[#This Row],[Buy QTY]]-Table3[[#This Row],[Sell QTY]] -> 278
B21: CCAVENUE | E21: 200 | F21: 18.9 | G21: 3780 | H21: =Table3[[#This Row],[Buy QTY]]-Table3[[#This Row],[Sell QTY]] -> -200
B22: CESC | E22: 185 | F22: 150.1 | G22: 13884.25 | H22: =Table3[[#This Row],[Buy QTY]]-Table3[[#This Row],[Sell QTY]] -> -185
B23: CHOLAHLDNG | C23: 100 | D23: 4103.9 | E23: 100 | F23: 33081.2 | G23: 1035.9 | H23: =Table3[[#This Row],[Buy QTY]]-Table3[[#This Row],[Sell QTY]] -> 0
B24: COALINDIA | C24: 999 | D24: 4864.2 | G24: -441757.8 | H24: =Table3[[#This Row],[Buy QTY]]-Table3[[#This Row],[Sell QTY]] -> 999
B25: CONCOR | C25: 400 | D25: 7183.3 | G25: -191555 | H25: =Table3[[#This Row],[Buy QTY]]-Table3[[#This Row],[Sell QTY]] -> 400
B26: DEEPAKFERT | C26: 205 | D26: 975 | G26: -199875 | H26: =Table3[[#This Row],[Buy QTY]]-Table3[[#This Row],[Sell QTY]] -> 205
B27: DEEPAKNTR | C27: 75 | D27: 5500 | G27: -206235 | H27: =Table3[[#This Row],[Buy QTY]]-Table3[[#This Row],[Sell QTY]] -> 75
B28: ECLERX | C28: 27 | D28: 10725 | G28: -96835 | H28: =Table3[[#This Row],[Buy QTY]]-Table3[[#This Row],[Sell QTY]] -> 27
B29: EMAMIPAP | C29: 40 | D29: 116 | E29: 556 | F29: 2512.46 | G29: 58856.16 | H29: =Table3[[#This Row],[Buy QTY]]-Table3[[#This Row],[Sell QTY]] -> -516
B30: EQUITASBNK | C30: 2000 | D30: 393.4 | G30: -196700 | H30: =Table3[[#This Row],[Buy QTY]]-Table3[[#This Row],[Sell QTY]] -> 2000
B31: ETERNAL | C31: 999 | D31: 217 | G31: -216783 | H31: =Table3[[#This Row],[Buy QTY]]-Table3[[#This Row],[Sell QTY]] -> 999
B32: FLFL | E32: 2600 | F32: 86.2 | G32: 13793 | H32: =Table3[[#This Row],[Buy QTY]]-Table3[[#This Row],[Sell QTY]] -> -2600
B33: GHCL | C33: 6 | D33: 1062.05 | G33: -3186.15 | H33: =Table3[[#This Row],[Buy QTY]]-Table3[[#This Row],[Sell QTY]] -> 6
B34: GICRE | C34: 3276 | D34: 9512.05 | G34: -969723.95 | H34: =Table3[[#This Row],[Buy QTY]]-Table3[[#This Row],[Sell QTY]] -> 3276
B35: GLS | E35: 594 | F35: 4906.65 | G35: 323801.85 | H35: =Table3[[#This Row],[Buy QTY]]-Table3[[#This Row],[Sell QTY]] -> -594
B36: GODREJIND | C36: 360 | D36: 4123.15 | G36: -296979 | H36: =Table3[[#This Row],[Buy QTY]]-Table3[[#This Row],[Sell QTY]] -> 360
B37: GODREJPROP | E37: 504 | F37: 23131.5 | G37: 832806.9 | H37: =Table3[[#This Row],[Buy QTY]]-Table3[[#This Row],[Sell QTY]] -> -504
B38: GOKEX | C38: 3000 | D38: 4824.75 | E38: 3000 | F38: 5148.9 | G38: 227400 | H38: =Table3[[#This Row],[Buy QTY]]-Table3[[#This Row],[Sell QTY]] -> 0
B39: GSPL | C39: 555 | D39: 17627.45 | G39: -160373.55 | H39: =Table3[[#This Row],[Buy QTY]]-Table3[[#This Row],[Sell QTY]] -> 555
B40: GUJGASLTD | C40: 370 | D40: 1304.75 | G40: -123180.9 | H40: =Table3[[#This Row],[Buy QTY]]-Table3[[#This Row],[Sell QTY]] -> 370
B41: HAL | C41: 255 | D41: 14516.9 | E41: 230 | F41: 56301.6 | G41: -96542.879 | H41: =Table3[[#This Row],[Buy QTY]]-Table3[[#This Row],[Sell QTY]] -> 25
...

Sheet Open_positions
B2: Symbols | C2: Qty | D2: Cost | E2: Cashflow | F2: Market price as on 14-04-2026 | G2: Cashflow
B3: ABB | C3: 34 | D3: =E3/C3 -> -5753 | E3: -195602 | F3: 6182.5 | G3: =F3*C3 -> 210205
B4: ABCGAS | C4: 945 | D4: =E4/C4 -> -38.963175 | E4: -36820.2 | F4: 118.4 | G4: =F4*C4 -> 111888
B5: ABFRL | C5: 3000 | D5: =E5/C5 -> -316.75 | E5: -950250 | F5: 64.85 | G5: =F5*C5 -> 194550
B6: ANUBHAV | C6: 2723 | D6: =E6/C6 -> -11.260264 | E6: -30661.7 | F6: 145.2 | G6: =F6*C6 -> 395379.6
B7: AXISBANK | C7: 57 | D7: =E7/C7 -> -948.5 | E7: -54064.5 | F7: 1255.8 | G7: =F7*C7 -> 71580.6
B8: BAJFINANCE | C8: 144 | D8: =E8/C8 -> -6932 | E8: -998208 | F8: 6842.3 | G8: =F8*C8 -> 985291.2
B9: BDL | C9: 100 | D9: =E9/C9 -> -1067.7625 | E9: -106776.25 | F9: 1672.4 | G9: =F9*C9 -> 167240
B10: BNRSEC | C10: 1625 | D10: =E10/C10 -> -17.143077 | E10: -27857.5 | F10: 98.75 | G10: =F10*C10 -> 160468.75
B11: BRITANNIA | C11: 40 | D11: =E11/C11 -> -5546.1875 | E11: -221847.5 | F11: 5012.6 | G11: =F11*C11 -> 200504
B12: CAMS | C12: 278 | D12: =E12/C12 -> -708.20162 | E12: -196880.05 | F12: 2782.15 | G12: =F12*C12 -> 773437.7
B13: COALINDIA | C13: 999 | D13: =E13/C13 -> -442.2 | E13: -441757.8 | F13: 412.25 | G13: =F13*C13 -> 411837.75
B14: CONCOR | C14: 400 | D14: =E14/C14 -> -478.8875 | E14: -191555 | F14: 1028.9 | G14: =F14*C14 -> 411560
... B70: YESBANK | C70: 25400 | D70: =E70/C70 -> -24.4199 | E70: -620265.46 | F70: 27.4 | G70: =F70*C70 -> 695960
